Internal Server Error: /actualizar_estado_reporte/9944036a-d2bb-43c8-bca2-f11591382e29/RESUELTO/
"POST /actualizar_estado_reporte/9944036a-d2bb-43c8-bca2-f11591382e29/RESUELTO/ HTTP/1.1" 500 249
Internal Server Error: /actualizar_estado_reporte/9944036a-d2bb-43c8-bca2-f11591382e29/RECHAZADO/
"POST /actualizar_estado_reporte/9944036a-d2bb-43c8-bca2-f11591382e29/RECHAZADO/ HTTP/1.1" 500 221
Internal Server Error: /actualizar_estado_reporte/9944036a-d2bb-43c8-bca2-f11591382e29/RECHAZADO/
"POST /actualizar_estado_reporte/9944036a-d2bb-43c8-bca2-f11591382e29/RECHAZADO/ HTTP/1.1" 500 222
Internal Server Error: /actualizar_estado_revisado/49b79aad-8135-4329-b707-24d7108664ef/
Traceback (most recent call last):
  File "C:\Users\Brian\AppData\Local\Programs\Python\Python312\Lib\site-packages\django\core\handlers\exception.py", line 55, in inner
    response = get_response(request)
               ^^^^^^^^^^^^^^^^^^^^^
  File "C:\Users\Brian\AppData\Local\Programs\Python\Python312\Lib\site-packages\django\core\handlers\base.py", line 197, in _get_response
    response = wrapped_callback(request, *callback_args, **callback_kwargs)
               ^^^^^^^^^^^^^^^^^^^^^^^^^^^^^^^^^^^^^^^^^^^^^^^^^^^^^^^^^^^^
  File "C:\Users\Brian\Desktop\CAPSTONE_004D\upcyclewear\aplicacion\views.py", line 672, in actualizar_estado_revisado
    reporte = ReporteUsuario.objects.get(id=reporte_id)
              ^^^^^^^^^^^^^^^^^^^^^^^^^^^^^^^^^^^^^^^^^
  File "C:\Users\Brian\AppData\Local\Programs\Python\Python312\Lib\site-packages\django\db\models\manager.py", line 87, in manager_method
    return getattr(self.get_queryset(), name)(*args, **kwargs)
           ^^^^^^^^^^^^^^^^^^^^^^^^^^^^^^^^^^^^^^^^^^^^^^^^^^^
  File "C:\Users\Brian\AppData\Local\Programs\Python\Python312\Lib\site-packages\django\db\models\query.py", line 635, in get
    clone = self._chain() if self.query.combinator else self.filter(*args, **kwargs)
                                                        ^^^^^^^^^^^^^^^^^^^^^^^^^^^^
  File "C:\Users\Brian\AppData\Local\Programs\Python\Python312\Lib\site-packages\django\db\models\query.py", line 1476, in filter
    return self._filter_or_exclude(False, args, kwargs)
           ^^^^^^^^^^^^^^^^^^^^^^^^^^^^^^^^^^^^^^^^^^^^
  File "C:\Users\Brian\AppData\Local\Programs\Python\Python312\Lib\site-packages\django\db\models\query.py", line 1494, in _filter_or_exclude
    clone._filter_or_exclude_inplace(negate, args, kwargs)
  File "C:\Users\Brian\AppData\Local\Programs\Python\Python312\Lib\site-packages\django\db\models\query.py", line 1501, in _filter_or_exclude_inplace
    self._query.add_q(Q(*args, **kwargs))
  File "C:\Users\Brian\AppData\Local\Programs\Python\Python312\Lib\site-packages\django\db\models\sql\query.py", line 1609, in add_q
    clause, _ = self._add_q(q_object, self.used_aliases)
                ^^^^^^^^^^^^^^^^^^^^^^^^^^^^^^^^^^^^^^^^
  File "C:\Users\Brian\AppData\Local\Programs\Python\Python312\Lib\site-packages\django\db\models\sql\query.py", line 1641, in _add_q
    child_clause, needed_inner = self.build_filter(
                                 ^^^^^^^^^^^^^^^^^^
  File "C:\Users\Brian\AppData\Local\Programs\Python\Python312\Lib\site-packages\django\db\models\sql\query.py", line 1491, in build_filter
    lookups, parts, reffed_expression = self.solve_lookup_type(arg, summarize)
                                        ^^^^^^^^^^^^^^^^^^^^^^^^^^^^^^^^^^^^^^
  File "C:\Users\Brian\AppData\Local\Programs\Python\Python312\Lib\site-packages\django\db\models\sql\query.py", line 1303, in solve_lookup_type
    _, field, _, lookup_parts = self.names_to_path(lookup_splitted, self.get_meta())
                                ^^^^^^^^^^^^^^^^^^^^^^^^^^^^^^^^^^^^^^^^^^^^^^^^^^^^
  File "C:\Users\Brian\AppData\Local\Programs\Python\Python312\Lib\site-packages\django\db\models\sql\query.py", line 1768, in names_to_path
    raise FieldError(
django.core.exceptions.FieldError: Cannot resolve keyword 'id' into field. Choices are: descripcion, estado, fecha_actualizacion, fecha_creacion, id_reporte, motivo, resultado, usuario_reportado, usuario_reportado_id, usuario_reportante, usuario_reportante_id
"GET /actualizar_estado_revisado/49b79aad-8135-4329-b707-24d7108664ef/ HTTP/1.1" 500 119748
Internal Server Error: /actualizar_estado_revisado/9944036a-d2bb-43c8-bca2-f11591382e29/
Traceback (most recent call last):
  File "C:\Users\Brian\AppData\Local\Programs\Python\Python312\Lib\site-packages\django\core\handlers\exception.py", line 55, in inner
    response = get_response(request)
               ^^^^^^^^^^^^^^^^^^^^^
  File "C:\Users\Brian\AppData\Local\Programs\Python\Python312\Lib\site-packages\django\core\handlers\base.py", line 204, in _get_response
    self.check_response(response, callback)
  File "C:\Users\Brian\AppData\Local\Programs\Python\Python312\Lib\site-packages\django\core\handlers\base.py", line 332, in check_response
    raise ValueError(
ValueError: The view aplicacion.views.actualizar_estado_revisado didn't return an HttpResponse object. It returned None instead.
"GET /actualizar_estado_revisado/9944036a-d2bb-43c8-bca2-f11591382e29/ HTTP/1.1" 500 69348
Internal Server Error: /
Traceback (most recent call last):
  File "C:\Users\Brian\AppData\Local\Programs\Python\Python312\Lib\site-packages\django\contrib\sessions\backends\base.py", line 244, in _get_session
    return self._session_cache
           ^^^^^^^^^^^^^^^^^^^
AttributeError: 'SessionStore' object has no attribute '_session_cache'

During handling of the above exception, another exception occurred:

Traceback (most recent call last):
  File "C:\Users\Brian\AppData\Local\Programs\Python\Python312\Lib\site-packages\django\db\backends\base\base.py", line 279, in ensure_connection
    self.connect()
  File "C:\Users\Brian\AppData\Local\Programs\Python\Python312\Lib\site-packages\django\utils\asyncio.py", line 26, in inner
    return func(*args, **kwargs)
           ^^^^^^^^^^^^^^^^^^^^^
  File "C:\Users\Brian\AppData\Local\Programs\Python\Python312\Lib\site-packages\django\db\backends\base\base.py", line 256, in connect
    self.connection = self.get_new_connection(conn_params)
                      ^^^^^^^^^^^^^^^^^^^^^^^^^^^^^^^^^^^^
  File "C:\Users\Brian\AppData\Local\Programs\Python\Python312\Lib\site-packages\django\utils\asyncio.py", line 26, in inner
    return func(*args, **kwargs)
           ^^^^^^^^^^^^^^^^^^^^^
  File "C:\Users\Brian\AppData\Local\Programs\Python\Python312\Lib\site-packages\django\db\backends\oracle\base.py", line 253, in get_new_connection
    return Database.connect(
           ^^^^^^^^^^^^^^^^^
cx_Oracle.DatabaseError: ORA-12547: TNS:lost contact
Help: https://docs.oracle.com/error-help/db/ora-12547/

The above exception was the direct cause of the following exception:

Traceback (most recent call last):
  File "C:\Users\Brian\AppData\Local\Programs\Python\Python312\Lib\site-packages\asgiref\sync.py", line 518, in thread_handler
    raise exc_info[1]
  File "C:\Users\Brian\AppData\Local\Programs\Python\Python312\Lib\site-packages\django\core\handlers\exception.py", line 42, in inner
    response = await get_response(request)
               ^^^^^^^^^^^^^^^^^^^^^^^^^^^
  File "C:\Users\Brian\AppData\Local\Programs\Python\Python312\Lib\site-packages\asgiref\sync.py", line 518, in thread_handler
    raise exc_info[1]
  File "C:\Users\Brian\AppData\Local\Programs\Python\Python312\Lib\site-packages\django\core\handlers\base.py", line 253, in _get_response_async
    response = await wrapped_callback(
               ^^^^^^^^^^^^^^^^^^^^^^^
  File "C:\Users\Brian\AppData\Local\Programs\Python\Python312\Lib\site-packages\asgiref\sync.py", line 468, in __call__
    ret = await asyncio.shield(exec_coro)
          ^^^^^^^^^^^^^^^^^^^^^^^^^^^^^^^
  File "C:\Users\Brian\AppData\Local\Programs\Python\Python312\Lib\site-packages\asgiref\current_thread_executor.py", line 40, in run
    result = self.fn(*self.args, **self.kwargs)
             ^^^^^^^^^^^^^^^^^^^^^^^^^^^^^^^^^^
  File "C:\Users\Brian\AppData\Local\Programs\Python\Python312\Lib\site-packages\asgiref\sync.py", line 522, in thread_handler
    return func(*args, **kwargs)
           ^^^^^^^^^^^^^^^^^^^^^
  File "C:\Users\Brian\Desktop\CAPSTONE_004D\upcyclewear\aplicacion\views.py", line 33, in principal
    if request.user.is_authenticated:
       ^^^^^^^^^^^^^^^^^^^^^^^^^^^^^
  File "C:\Users\Brian\AppData\Local\Programs\Python\Python312\Lib\site-packages\django\utils\functional.py", line 251, in inner
    self._setup()
  File "C:\Users\Brian\AppData\Local\Programs\Python\Python312\Lib\site-packages\django\utils\functional.py", line 404, in _setup
    self._wrapped = self._setupfunc()
                    ^^^^^^^^^^^^^^^^^
  File "C:\Users\Brian\AppData\Local\Programs\Python\Python312\Lib\site-packages\django\contrib\auth\middleware.py", line 37, in <lambda>
    request.user = SimpleLazyObject(lambda: get_user(request))
                                            ^^^^^^^^^^^^^^^^^
  File "C:\Users\Brian\AppData\Local\Programs\Python\Python312\Lib\site-packages\django\contrib\auth\middleware.py", line 17, in get_user
    request._cached_user = auth.get_user(request)
                           ^^^^^^^^^^^^^^^^^^^^^^
  File "C:\Users\Brian\AppData\Local\Programs\Python\Python312\Lib\site-packages\django\contrib\auth\__init__.py", line 209, in get_user
    user_id = _get_user_session_key(request)
              ^^^^^^^^^^^^^^^^^^^^^^^^^^^^^^
  File "C:\Users\Brian\AppData\Local\Programs\Python\Python312\Lib\site-packages\django\contrib\auth\__init__.py", line 62, in _get_user_session_key
    return get_user_model()._meta.pk.to_python(request.session[SESSION_KEY])
                                               ~~~~~~~~~~~~~~~^^^^^^^^^^^^^
  File "C:\Users\Brian\AppData\Local\Programs\Python\Python312\Lib\site-packages\django\contrib\sessions\backends\base.py", line 55, in __getitem__
    return self._session[key]
           ^^^^^^^^^^^^^
  File "C:\Users\Brian\AppData\Local\Programs\Python\Python312\Lib\site-packages\django\contrib\sessions\backends\base.py", line 249, in _get_session
    self._session_cache = self.load()
                          ^^^^^^^^^^^
  File "C:\Users\Brian\AppData\Local\Programs\Python\Python312\Lib\site-packages\django\contrib\sessions\backends\db.py", line 55, in load
    s = self._get_session_from_db()
        ^^^^^^^^^^^^^^^^^^^^^^^^^^^
  File "C:\Users\Brian\AppData\Local\Programs\Python\Python312\Lib\site-packages\django\contrib\sessions\backends\db.py", line 34, in _get_session_from_db
    return self.model.objects.get(
           ^^^^^^^^^^^^^^^^^^^^^^^
  File "C:\Users\Brian\AppData\Local\Programs\Python\Python312\Lib\site-packages\django\db\models\manager.py", line 87, in manager_method
    return getattr(self.get_queryset(), name)(*args, **kwargs)
           ^^^^^^^^^^^^^^^^^^^^^^^^^^^^^^^^^^^^^^^^^^^^^^^^^^^
  File "C:\Users\Brian\AppData\Local\Programs\Python\Python312\Lib\site-packages\django\db\models\query.py", line 645, in get
    num = len(clone)
          ^^^^^^^^^^
  File "C:\Users\Brian\AppData\Local\Programs\Python\Python312\Lib\site-packages\django\db\models\query.py", line 382, in __len__
    self._fetch_all()
  File "C:\Users\Brian\AppData\Local\Programs\Python\Python312\Lib\site-packages\django\db\models\query.py", line 1928, in _fetch_all
    self._result_cache = list(self._iterable_class(self))
                         ^^^^^^^^^^^^^^^^^^^^^^^^^^^^^^^^
  File "C:\Users\Brian\AppData\Local\Programs\Python\Python312\Lib\site-packages\django\db\models\query.py", line 91, in __iter__
    results = compiler.execute_sql(
              ^^^^^^^^^^^^^^^^^^^^^
  File "C:\Users\Brian\AppData\Local\Programs\Python\Python312\Lib\site-packages\django\db\models\sql\compiler.py", line 1561, in execute_sql
    sql, params = self.as_sql()
                  ^^^^^^^^^^^^^
  File "C:\Users\Brian\AppData\Local\Programs\Python\Python312\Lib\site-packages\django\db\models\sql\compiler.py", line 775, in as_sql
    self.compile(self.where) if self.where is not None else ("", [])
    ^^^^^^^^^^^^^^^^^^^^^^^^
  File "C:\Users\Brian\AppData\Local\Programs\Python\Python312\Lib\site-packages\django\db\models\sql\compiler.py", line 557, in compile
    sql, params = node.as_sql(self, self.connection)
                  ^^^^^^^^^^^^^^^^^^^^^^^^^^^^^^^^^^
  File "C:\Users\Brian\AppData\Local\Programs\Python\Python312\Lib\site-packages\django\db\models\sql\where.py", line 151, in as_sql
    sql, params = compiler.compile(child)
                  ^^^^^^^^^^^^^^^^^^^^^^^
  File "C:\Users\Brian\AppData\Local\Programs\Python\Python312\Lib\site-packages\django\db\models\sql\compiler.py", line 555, in compile
    sql, params = vendor_impl(self, self.connection)
                  ^^^^^^^^^^^^^^^^^^^^^^^^^^^^^^^^^^
  File "C:\Users\Brian\AppData\Local\Programs\Python\Python312\Lib\site-packages\django\db\models\lookups.py", line 151, in as_oracle
    return lookup.as_sql(compiler, connection)
           ^^^^^^^^^^^^^^^^^^^^^^^^^^^^^^^^^^^
  File "C:\Users\Brian\AppData\Local\Programs\Python\Python312\Lib\site-packages\django\db\models\lookups.py", line 248, in as_sql
    rhs_sql = self.get_rhs_op(connection, rhs_sql)
              ^^^^^^^^^^^^^^^^^^^^^^^^^^^^^^^^^^^^
  File "C:\Users\Brian\AppData\Local\Programs\Python\Python312\Lib\site-packages\django\db\models\lookups.py", line 252, in get_rhs_op
    return connection.operators[self.lookup_name] % rhs
           ^^^^^^^^^^^^^^^^^^^^
  File "C:\Users\Brian\AppData\Local\Programs\Python\Python312\Lib\site-packages\django\db\backends\oracle\base.py", line 101, in __get__
    instance.cursor().close()
    ^^^^^^^^^^^^^^^^^
  File "C:\Users\Brian\AppData\Local\Programs\Python\Python312\Lib\site-packages\django\utils\asyncio.py", line 26, in inner
    return func(*args, **kwargs)
           ^^^^^^^^^^^^^^^^^^^^^
  File "C:\Users\Brian\AppData\Local\Programs\Python\Python312\Lib\site-packages\django\db\backends\base\base.py", line 320, in cursor
    return self._cursor()
           ^^^^^^^^^^^^^^
  File "C:\Users\Brian\AppData\Local\Programs\Python\Python312\Lib\site-packages\django\db\backends\base\base.py", line 296, in _cursor
    self.ensure_connection()
  File "C:\Users\Brian\AppData\Local\Programs\Python\Python312\Lib\site-packages\django\utils\asyncio.py", line 26, in inner
    return func(*args, **kwargs)
           ^^^^^^^^^^^^^^^^^^^^^
  File "C:\Users\Brian\AppData\Local\Programs\Python\Python312\Lib\site-packages\django\db\backends\base\base.py", line 278, in ensure_connection
    with self.wrap_database_errors:
  File "C:\Users\Brian\AppData\Local\Programs\Python\Python312\Lib\site-packages\django\db\utils.py", line 91, in __exit__
    raise dj_exc_value.with_traceback(traceback) from exc_value
  File "C:\Users\Brian\AppData\Local\Programs\Python\Python312\Lib\site-packages\django\db\backends\base\base.py", line 279, in ensure_connection
    self.connect()
  File "C:\Users\Brian\AppData\Local\Programs\Python\Python312\Lib\site-packages\django\utils\asyncio.py", line 26, in inner
    return func(*args, **kwargs)
           ^^^^^^^^^^^^^^^^^^^^^
  File "C:\Users\Brian\AppData\Local\Programs\Python\Python312\Lib\site-packages\django\db\backends\base\base.py", line 256, in connect
    self.connection = self.get_new_connection(conn_params)
                      ^^^^^^^^^^^^^^^^^^^^^^^^^^^^^^^^^^^^
  File "C:\Users\Brian\AppData\Local\Programs\Python\Python312\Lib\site-packages\django\utils\asyncio.py", line 26, in inner
    return func(*args, **kwargs)
           ^^^^^^^^^^^^^^^^^^^^^
  File "C:\Users\Brian\AppData\Local\Programs\Python\Python312\Lib\site-packages\django\db\backends\oracle\base.py", line 253, in get_new_connection
    return Database.connect(
           ^^^^^^^^^^^^^^^^^
django.db.utils.DatabaseError: ORA-12547: TNS:lost contact
Help: https://docs.oracle.com/error-help/db/ora-12547/
